<?xml version="1.0" ?>
<!-- =================================================================================== -->
<!-- |    This document was autogenerated by xacro from tita.urdf.xacro                | -->
<!-- |    EDITING THIS FILE BY HAND IS NOT RECOMMENDED                                 | -->
<!-- =================================================================================== -->
<robot name="tita">
  <material name="black">
    <color rgba="0.19607843137254902 0.19607843137254902 0.19607843137254902 1.0"/>
  </material>
  <material name="blue">
    <color rgba="0.0 0.0 0.8 1.0"/>
  </material>
  <material name="green">
    <color rgba="0.0 0.8 0.0 1.0"/>
  </material>
  <material name="grey">
    <color rgba="0.2 0.2 0.2 1.0"/>
  </material>
  <material name="silver">
    <color rgba="0.9137254901960784 0.9137254901960784 0.8470588235294118 1.0"/>
  </material>
  <material name="orange">
    <color rgba="1.0 0.4235294117647059 0.0392156862745098 1.0"/>
  </material>
  <material name="brown">
    <color rgba="0.8705882352941177 0.8117647058823529 0.7647058823529411 1.0"/>
  </material>
  <material name="red">
    <color rgba="0.8 0.0 0.0 1.0"/>
  </material>
  <material name="white">
    <color rgba="1.0 1.0 1.0 1.0"/>
  </material>
  <link name="base_link">
    <inertial>
      <origin rpy="0 0 0" xyz="0.01335116 3.5457E-06 0.01863129"/>
      <mass value="11.36226789"/>
      <inertia ixx="0.10777013" ixy="-0.00184576" ixz="0.01392083" iyy="0.25823486" iyz="-1.0712E-4" izz="0.3122104"/>
    </inertial>
    <visual>
      <origin rpy="0 0 0" xyz="0 0 0"/>
      <geometry>
        <mesh filename="../meshes/base_link.STL"/>
      </geometry>
      <material name="black"/>
    </visual>
    <collision>
      <origin rpy="0 0 0" xyz="0 0 0.0"/>
      <geometry>
        <box size="0.47 0.3 0.19"/>
        <!-- <mesh filename="package://tita_description/collision/base_link1.stl" /> -->
      </geometry>
    </collision>
  </link>
  <link name="spad">
  </link>
  <joint name="spad" type="fixed">
    <origin rpy="2.199 0 1.5708" xyz="0.24052 -0.0019 0.064455"/>
    <parent link="base_link"/>
    <child link="spad"/>
    <axis xyz="0 0 0"/>
  </joint>
  <link name="spad1">
  </link>
  <joint name="spad1" type="fixed">
    <origin rpy="2.632 0 1.5708" xyz="0.21953 -0.0019 -0.030142"/>
    <parent link="base_link"/>
    <child link="spad1"/>
    <axis xyz="0 0 0"/>
  </joint>
  <link name="left_camera">
  </link>
  <joint name="left_camera" type="fixed">
    <origin rpy="1.5708 0 1.5708" xyz="0.23416 0.075 0.04036"/>
    <parent link="base_link"/>
    <child link="left_camera"/>
    <axis xyz="0 0 0"/>
  </joint>
  <link name="ch201">
  </link>
  <joint name="ch201" type="fixed">
    <origin rpy="1.1693 0 1.5708" xyz="0.23782 0 0.018636"/>
    <parent link="base_link"/>
    <child link="ch201"/>
    <axis xyz="0 0 0"/>
  </joint>
  <link name="right_camara">
  </link>
  <joint name="right_camera" type="fixed">
    <origin rpy="1.5708 0 1.5708" xyz="0.23416 -0.075001 0.04036"/>
    <parent link="base_link"/>
    <child link="right_camara"/>
    <axis xyz="0 0 0"/>
  </joint>
  <joint name="imu_joint" type="fixed">
    <parent link="base_link"/>
    <child link="imu_link"/>
    <origin rpy="0 0 0" xyz="0 0 0"/>
  </joint>
  <link name="imu_link">
    <inertial>
      <mass value="0.001"/>
      <origin rpy="0 0 0" xyz="0 0 0"/>
      <inertia ixx="0.0001" ixy="0" ixz="0" iyy="0.0001" iyz="0" izz="0.0001"/>
    </inertial>
    <visual>
      <origin rpy="0 0 0" xyz="0 0 0"/>
      <geometry>
        <box size="0.001 0.001 0.001"/>
      </geometry>
      <material name="red"/>
    </visual>
    <collision>
      <origin rpy="0 0 0" xyz="0 0 0"/>
      <geometry>
        <box size=".001 .001 .001"/>
      </geometry>
    </collision>
  </link>
  <link name="left_leg_1">
    <inertial>
      <origin rpy="0 0 0" xyz="0.001602 0.000050 0.000638"/>
      <mass value="2.064"/>
      <inertia ixx="0.004370" ixy="0.000001" ixz="0.000055" iyy="0.004060" iyz="-0.000001" izz="0.003268"/>
    </inertial>
    <visual>
      <origin rpy="0 0 0" xyz="0 0 0"/>
      <geometry>
        <mesh filename="../meshes/left_leg_1.STL"/>
      </geometry>
      <material name="black"/>
    </visual>
  </link>
  <joint name="joint_left_leg_1" type="revolute">
    <origin rpy="1.5708 0 1.5708" xyz="0 0.0895 0"/>
    <parent link="base_link"/>
    <child link="left_leg_1"/>
    <axis xyz="0 0 1"/>
    <limit effort="80" lower="-0.785398" upper="0.785398" velocity="15"/>
  </joint>
  <link name="left_leg_2">
    <inertial>
      <origin rpy="0 0 0" xyz="0.021183 0.000354 -0.028971"/>
      <mass value="3.018005"/>
      <inertia ixx="0.005749" ixy="-0.000167" ixz="-0.001863" iyy="0.014415" iyz="-0.000122" izz="0.013964"/>
    </inertial>
    <visual>
      <origin rpy="0 0 0" xyz="0 0 0"/>
      <geometry>
        <mesh filename="../meshes/left_leg_2.STL"/>
      </geometry>
      <material name="black"/>
    </visual>
  </link>
  <joint name="joint_left_leg_2" type="revolute">
    <origin rpy="-1.5708 0 -1.5708" xyz="0.1426 0 0"/>
    <parent link="left_leg_1"/>
    <child link="left_leg_2"/>
    <axis xyz="0 0 1"/>
    <limit effort="60" lower="-1.919862" upper="3.490659" velocity="15"/>
  </joint>
  <link name="left_leg_3">
    <inertial>
      <origin rpy="0 0 0" xyz="0.095348 0.011698 0.001838"/>
      <mass value="0.57244"/>
      <inertia ixx="0.000363" ixy="0.000237" ixz="-0.000109" iyy="0.004094 " iyz="0.000017" izz="0.004292"/>
    </inertial>
    <visual>
      <origin rpy="0 0 0" xyz="0 0 0"/>
      <geometry>
        <mesh filename="../meshes/left_leg_3.STL"/>
      </geometry>
      <material name="black"/>
    </visual>
    <collision>
      <origin rpy="0 0 -0.131" xyz="0.1 0.021 -0.002"/>
      <geometry>
        <box size="0.2 0.07 0.05"/>
      </geometry>
    </collision>
  </link>
  <joint name="joint_left_leg_3" type="revolute">
    <origin rpy="0 0 0" xyz="0.2 0 0"/>
    <parent link="left_leg_2"/>
    <child link="left_leg_3"/>
    <axis xyz="0 0 1"/>
    <limit effort="60" lower="-2.670354" upper="-0.698132" velocity="15"/>
  </joint>
  <link name="left_leg_4">
    <inertial>
      <origin rpy="0 0 0" xyz="-2.267E-06 -1.6471E-06 -0.00095616"/>
      <mass value="1.5094"/>
      <inertia ixx="0.003615" ixy="6.9816E-06" ixz="-2.3224E-07" iyy="0.003574" iyz="-1.7712E-08" izz="0.006905"/>
    </inertial>
    <visual>
      <origin rpy="0 0 0" xyz="0 0 0"/>
      <geometry>
        <mesh filename="../meshes/left_leg_4.STL"/>
      </geometry>
      <material name="black"/>
    </visual>
    <collision>
      <origin rpy="0 0 0" xyz="0 0 0"/>
      <geometry>
        <cylinder length="0.034" radius="0.0925"/>
      </geometry>
    </collision>
  </link>
  <joint name="joint_left_leg_4" type="revolute">
    <origin rpy="0 0 0" xyz="0.2 0 0.0514"/>
    <parent link="left_leg_3"/>
    <child link="left_leg_4"/>
    <axis xyz="0 0 1"/>
    <limit effort="10" lower="-6.283185e4" upper="6.283185e4" velocity="50"/>
  </joint>
  <link name="right_leg_1">
    <inertial>
      <origin rpy="0 0 0" xyz="-0.001602 0.000050 0.000638"/>
      <mass value="2.064"/>
      <inertia ixx="0.004370" ixy="-0.000001" ixz="-0.000055" iyy="0.004060" iyz="-0.000001" izz="0.003268"/>
    </inertial>
    <visual>
      <origin rpy="0 0 0" xyz="0 0 0"/>
      <geometry>
        <mesh filename="../meshes/right_leg_1.STL"/>
      </geometry>
      <material name="black"/>
    </visual>
  </link>
  <joint name="joint_right_leg_1" type="revolute">
    <origin rpy="1.5708 0 1.5708" xyz="0 -0.0895 0"/>
    <parent link="base_link"/>
    <child link="right_leg_1"/>
    <axis xyz="0 0 1"/>
    <limit effort="80" lower="-0.785398" upper="0.785398" velocity="15"/>
  </joint>
  <link name="right_leg_2">
    <inertial>
      <origin rpy="0 0 0" xyz="0.021183 0.000354 0.028971"/>
      <mass value="3.018005"/>
      <inertia ixx="0.005749" ixy="-0.000167" ixz="0.001863" iyy="0.014415" iyz="0.000122" izz="0.013964"/>
    </inertial>
    <visual>
      <origin rpy="0 0 0" xyz="0 0 0"/>
      <geometry>
        <mesh filename="../meshes/right_leg_2.STL"/>
      </geometry>
      <material name="black"/>
    </visual>
  </link>
  <joint name="joint_right_leg_2" type="revolute">
    <origin rpy="-1.5708 0 -1.5708" xyz="-0.1426 0 0"/>
    <parent link="right_leg_1"/>
    <child link="right_leg_2"/>
    <axis xyz="0 0 1"/>
    <limit effort="60" lower="-1.919862" upper="3.490659" velocity="15"/>
  </joint>
  <link name="right_leg_3">
    <inertial>
      <origin rpy="0 0 0" xyz="0.095348 0.011698 -0.001838"/>
      <mass value="0.57244"/>
      <inertia ixx="0.000363" ixy="0.000237" ixz="0.000109" iyy="0.004094 " iyz="-0.000017" izz="0.004292"/>
    </inertial>
    <visual>
      <origin rpy="0 0 0" xyz="0 0 0"/>
      <geometry>
        <mesh filename="../meshes/right_leg_3.STL"/>
      </geometry>
      <material name="black"/>
    </visual>
    <collision>
      <origin rpy="0 0 -0.131" xyz="0.1 0.021 -0.002"/>
      <geometry>
        <box size="0.2 0.07 0.05"/>
      </geometry>
    </collision>
  </link>
  <joint name="joint_right_leg_3" type="revolute">
    <origin rpy="0 0 0" xyz="0.2 0 0"/>
    <parent link="right_leg_2"/>
    <child link="right_leg_3"/>
    <axis xyz="0 0 1"/>
    <limit effort="60" lower="-2.670354" upper="-0.698132" velocity="15"/>
  </joint>
  <link name="right_leg_4">
    <inertial>
      <origin rpy="0 0 0" xyz="-2.3798E-06 -1.5854E-06 0.00095595"/>
      <mass value="1.5094"/>
      <inertia ixx="0.003615" ixy="7.0548E-06" ixz="2.3146E-07" iyy="0.003574" iyz="1.9287E-08" izz="0.006905"/>
    </inertial>
    <visual>
      <origin rpy="0 0 0" xyz="0 0 0"/>
      <geometry>
        <mesh filename="../meshes/right_leg_4.STL"/>
      </geometry>
      <material name="black"/>
    </visual>
    <collision>
      <origin rpy="0 0 0" xyz="0 0 0"/>
      <geometry>
        <cylinder length="0.034" radius="0.0925"/>
      </geometry>
    </collision>
  </link>
  <joint name="joint_right_leg_4" type="revolute">
    <origin rpy="0 0 0" xyz="0.2 0 -0.0514"/>
    <parent link="right_leg_3"/>
    <child link="right_leg_4"/>
    <axis xyz="0 0 1"/>
    <limit effort="10" lower="-6.283185e4" upper="6.283185e4" velocity="50"/>
  </joint>
</robot>
